2021-01-09 15:49:20,659, DEBUG, root, Бот был успешно создан
2021-01-09 15:49:20,660, INFO, root, Отправлен запрос для проверки домашки
2021-01-09 15:50:09,205, DEBUG, root, Бот был успешно создан
2021-01-09 15:50:09,206, INFO, root, Отправлен запрос для проверки домашки
2021-01-09 15:50:09,479, DEBUG, telegram.bot, Entering: send_message
2021-01-09 15:50:09,479, DEBUG, telegram.vendor.ptb_urllib3.urllib3.connectionpool, Starting new HTTPS connection (1): api.telegram.org
2021-01-09 15:50:09,769, DEBUG, telegram.vendor.ptb_urllib3.urllib3.connectionpool, https://api.telegram.org:443 "POST /bot1415873638:AAFaNq5fitqj7HraQWi5MOqvfOrs4P-UvFA/sendMessage HTTP/1.1" 400 73
2021-01-09 15:50:09,770, ERROR, root, Бот не смог отправить сообщение из-за ошибки: Chat not found
2021-01-09 15:50:21,823, DEBUG, root, Бот был успешно создан
2021-01-09 15:50:21,823, INFO, root, Отправлен запрос для проверки домашки
2021-01-09 15:50:22,042, ERROR, root, Бот столкнулся с ошибкой: "Запрос домашней работы провалился из-за ошибки: {'error': 'Wrong from_date format'}"
2021-01-09 15:50:22,042, DEBUG, telegram.bot, Entering: send_message
2021-01-09 15:50:22,043, DEBUG, telegram.vendor.ptb_urllib3.urllib3.connectionpool, Starting new HTTPS connection (1): api.telegram.org
2021-01-09 15:50:22,383, DEBUG, telegram.vendor.ptb_urllib3.urllib3.connectionpool, https://api.telegram.org:443 "POST /bot1415873638:AAFaNq5fitqj7HraQWi5MOqvfOrs4P-UvFA/sendMessage HTTP/1.1" 400 73
2021-01-09 15:50:22,383, ERROR, root, Бот не смог отправить сообщение из-за ошибки: Chat not found
2021-01-09 15:51:00,185, DEBUG, root, Бот был успешно создан
2021-01-09 15:51:00,185, INFO, root, Отправлен запрос для проверки домашки
2021-01-09 15:51:00,413, ERROR, root, Бот столкнулся с ошибкой: "Запрос домашней работы провалился из-за ошибки: {'error': 'Wrong from_date format'}"
2021-01-09 15:51:00,414, DEBUG, telegram.bot, Entering: send_message
2021-01-09 15:51:00,414, DEBUG, telegram.vendor.ptb_urllib3.urllib3.connectionpool, Starting new HTTPS connection (1): api.telegram.org
2021-01-09 15:51:00,712, DEBUG, telegram.vendor.ptb_urllib3.urllib3.connectionpool, https://api.telegram.org:443 "POST /bot1415873638:AAFaNq5fitqj7HraQWi5MOqvfOrs4P-UvFA/sendMessage HTTP/1.1" 200 668
2021-01-09 15:51:00,712, DEBUG, telegram.bot, {'message_id': 165, 'date': 1610189460, 'chat': {'id': 1081293835, 'type': 'private', 'first_name': 'Alexey', 'last_name': 'Loguntsov'}, 'text': 'Бот столкнулся с ошибкой: "Запрос домашней работы провалился из-за ошибки: {\'error\': \'Wrong from_date format\'}"', 'entities': [], 'caption_entities': [], 'photo': [], 'new_chat_members': [], 'new_chat_photo': [], 'delete_chat_photo': False, 'group_chat_created': False, 'supergroup_chat_created': False, 'channel_chat_created': False, 'from': {'id': 1415873638, 'first_name': 'LoguntsovAE', 'is_bot': True, 'username': 'LoguntsovAE_bot'}}
2021-01-09 15:51:00,713, DEBUG, telegram.bot, Exiting: send_message
2021-01-09 15:51:00,713, INFO, root, Ботом отправленно сообщение о статусе домашки. Текст сообщения:"Бот столкнулся с ошибкой: "Запрос домашней работы провалился из-за ошибки: {'error': 'Wrong from_date format'}""
2021-01-09 15:51:46,910, DEBUG, root, Бот был успешно создан
2021-01-09 15:51:46,911, INFO, root, Отправлен запрос для проверки домашки
2021-01-09 15:52:01,636, DEBUG, root, Бот был успешно создан
2021-01-09 15:52:01,636, INFO, root, Отправлен запрос для проверки домашки
2021-01-09 15:52:01,879, ERROR, root, Бот столкнулся с ошибкой: "Запрос домашней работы провалился из-за ошибки: {'error': 'Wrong from_date format'}"
2021-01-09 15:52:01,879, DEBUG, telegram.bot, Entering: send_message
2021-01-09 15:52:01,880, DEBUG, telegram.vendor.ptb_urllib3.urllib3.connectionpool, Starting new HTTPS connection (1): api.telegram.org
2021-01-09 15:52:02,268, DEBUG, telegram.vendor.ptb_urllib3.urllib3.connectionpool, https://api.telegram.org:443 "POST /bot1415873638:AAFaNq5fitqj7HraQWi5MOqvfOrs4P-UvFA/sendMessage HTTP/1.1" 200 668
2021-01-09 15:52:02,269, DEBUG, telegram.bot, {'message_id': 166, 'date': 1610189522, 'chat': {'id': 1081293835, 'type': 'private', 'first_name': 'Alexey', 'last_name': 'Loguntsov'}, 'text': 'Бот столкнулся с ошибкой: "Запрос домашней работы провалился из-за ошибки: {\'error\': \'Wrong from_date format\'}"', 'entities': [], 'caption_entities': [], 'photo': [], 'new_chat_members': [], 'new_chat_photo': [], 'delete_chat_photo': False, 'group_chat_created': False, 'supergroup_chat_created': False, 'channel_chat_created': False, 'from': {'id': 1415873638, 'first_name': 'LoguntsovAE', 'is_bot': True, 'username': 'LoguntsovAE_bot'}}
2021-01-09 15:52:02,269, DEBUG, telegram.bot, Exiting: send_message
2021-01-09 15:52:02,269, INFO, root, Ботом отправленно сообщение о статусе домашки. Текст сообщения:"Бот столкнулся с ошибкой: "Запрос домашней работы провалился из-за ошибки: {'error': 'Wrong from_date format'}""
2021-01-09 15:53:02,899, DEBUG, root, Бот был успешно создан
2021-01-09 15:53:02,899, INFO, root, Отправлен запрос для проверки домашки
2021-01-09 15:53:03,143, ERROR, root, Бот столкнулся с ошибкой: 'params'
2021-01-09 15:53:03,143, DEBUG, telegram.bot, Entering: send_message
2021-01-09 15:53:03,144, DEBUG, telegram.vendor.ptb_urllib3.urllib3.connectionpool, Starting new HTTPS connection (1): api.telegram.org
2021-01-09 15:53:03,450, DEBUG, telegram.vendor.ptb_urllib3.urllib3.connectionpool, https://api.telegram.org:443 "POST /bot1415873638:AAFaNq5fitqj7HraQWi5MOqvfOrs4P-UvFA/sendMessage HTTP/1.1" 200 389
2021-01-09 15:53:03,451, DEBUG, telegram.bot, {'message_id': 167, 'date': 1610189583, 'chat': {'id': 1081293835, 'type': 'private', 'first_name': 'Alexey', 'last_name': 'Loguntsov'}, 'text': "Бот столкнулся с ошибкой: 'params'", 'entities': [], 'caption_entities': [], 'photo': [], 'new_chat_members': [], 'new_chat_photo': [], 'delete_chat_photo': False, 'group_chat_created': False, 'supergroup_chat_created': False, 'channel_chat_created': False, 'from': {'id': 1415873638, 'first_name': 'LoguntsovAE', 'is_bot': True, 'username': 'LoguntsovAE_bot'}}
2021-01-09 15:53:03,451, DEBUG, telegram.bot, Exiting: send_message
2021-01-09 15:53:03,451, INFO, root, Ботом отправленно сообщение о статусе домашки. Текст сообщения:"Бот столкнулся с ошибкой: 'params'"
2021-01-09 15:53:12,644, DEBUG, root, Бот был успешно создан
2021-01-09 15:53:12,644, INFO, root, Отправлен запрос для проверки домашки
2021-01-09 15:53:12,914, ERROR, root, Бот столкнулся с ошибкой: "По запросу: https://praktikum.yandex.ru/api/user_api/homework_statuses/, {'from_date': 'current_timestamp'}, {'Authorization': 'OAuth AgAAAAAoc5wqAAYckc67wQ4UHEheuLDz0_25rEA'} получена ошибка: {'error': 'Wrong from_date format'}"
2021-01-09 15:53:12,915, DEBUG, telegram.bot, Entering: send_message
2021-01-09 15:53:12,915, DEBUG, telegram.vendor.ptb_urllib3.urllib3.connectionpool, Starting new HTTPS connection (1): api.telegram.org
2021-01-09 15:53:13,207, DEBUG, telegram.vendor.ptb_urllib3.urllib3.connectionpool, https://api.telegram.org:443 "POST /bot1415873638:AAFaNq5fitqj7HraQWi5MOqvfOrs4P-UvFA/sendMessage HTTP/1.1" 200 780
2021-01-09 15:53:13,207, DEBUG, telegram.bot, {'message_id': 168, 'date': 1610189593, 'chat': {'id': 1081293835, 'type': 'private', 'first_name': 'Alexey', 'last_name': 'Loguntsov'}, 'text': 'Бот столкнулся с ошибкой: "По запросу: https://praktikum.yandex.ru/api/user_api/homework_statuses/, {\'from_date\': \'current_timestamp\'}, {\'Authorization\': \'OAuth AgAAAAAoc5wqAAYckc67wQ4UHEheuLDz0_25rEA\'} получена ошибка: {\'error\': \'Wrong from_date format\'}"', 'entities': [{'type': 'url', 'offset': 39, 'length': 59}], 'caption_entities': [], 'photo': [], 'new_chat_members': [], 'new_chat_photo': [], 'delete_chat_photo': False, 'group_chat_created': False, 'supergroup_chat_created': False, 'channel_chat_created': False, 'from': {'id': 1415873638, 'first_name': 'LoguntsovAE', 'is_bot': True, 'username': 'LoguntsovAE_bot'}}
2021-01-09 15:53:13,208, DEBUG, telegram.bot, Exiting: send_message
2021-01-09 15:53:13,208, INFO, root, Ботом отправленно сообщение о статусе домашки. Текст сообщения:"Бот столкнулся с ошибкой: "По запросу: https://praktikum.yandex.ru/api/user_api/homework_statuses/, {'from_date': 'current_timestamp'}, {'Authorization': 'OAuth AgAAAAAoc5wqAAYckc67wQ4UHEheuLDz0_25rEA'} получена ошибка: {'error': 'Wrong from_date format'}""
2021-01-09 15:53:33,008, DEBUG, root, Бот был успешно создан
2021-01-09 15:53:33,008, INFO, root, Отправлен запрос для проверки домашки
2021-01-09 15:53:33,235, ERROR, root, Бот столкнулся с ошибкой: "По запросу: https://praktikum.yandex.ru/api/user_api/homework_statuses/, {'from_date': 'current_timestamp'}, {'Authorization': 'OAuth AgAAAAAoc5wqAAYckc67wQ4UHEheuLDz0_25rEA'} получена ошибка: {'error': 'Wrong from_date format'}"
2021-01-09 15:53:33,235, DEBUG, telegram.bot, Entering: send_message
2021-01-09 15:53:33,235, DEBUG, telegram.vendor.ptb_urllib3.urllib3.connectionpool, Starting new HTTPS connection (1): api.telegram.org
2021-01-09 15:53:33,552, DEBUG, telegram.vendor.ptb_urllib3.urllib3.connectionpool, https://api.telegram.org:443 "POST /bot1415873638:AAFaNq5fitqj7HraQWi5MOqvfOrs4P-UvFA/sendMessage HTTP/1.1" 200 780
2021-01-09 15:53:33,553, DEBUG, telegram.bot, {'message_id': 169, 'date': 1610189613, 'chat': {'id': 1081293835, 'type': 'private', 'first_name': 'Alexey', 'last_name': 'Loguntsov'}, 'text': 'Бот столкнулся с ошибкой: "По запросу: https://praktikum.yandex.ru/api/user_api/homework_statuses/, {\'from_date\': \'current_timestamp\'}, {\'Authorization\': \'OAuth AgAAAAAoc5wqAAYckc67wQ4UHEheuLDz0_25rEA\'} получена ошибка: {\'error\': \'Wrong from_date format\'}"', 'entities': [{'type': 'url', 'offset': 39, 'length': 59}], 'caption_entities': [], 'photo': [], 'new_chat_members': [], 'new_chat_photo': [], 'delete_chat_photo': False, 'group_chat_created': False, 'supergroup_chat_created': False, 'channel_chat_created': False, 'from': {'id': 1415873638, 'first_name': 'LoguntsovAE', 'is_bot': True, 'username': 'LoguntsovAE_bot'}}
2021-01-09 15:53:33,553, DEBUG, telegram.bot, Exiting: send_message
2021-01-09 15:53:33,554, INFO, root, Ботом отправленно сообщение о статусе домашки. Текст сообщения:"Бот столкнулся с ошибкой: "По запросу: https://praktikum.yandex.ru/api/user_api/homework_statuses/, {'from_date': 'current_timestamp'}, {'Authorization': 'OAuth AgAAAAAoc5wqAAYckc67wQ4UHEheuLDz0_25rEA'} получена ошибка: {'error': 'Wrong from_date format'}""
2021-01-09 15:55:21,644, DEBUG, root, Бот был успешно создан
2021-01-09 15:55:21,644, INFO, root, Отправлен запрос для проверки домашки
2021-01-09 15:55:21,880, ERROR, root, Бот столкнулся с ошибкой: По запросу: https://praktikum.yandex.ru/api/user_api/homework_statuses/, {'from_date': 'current_timestamp'}, {'Authorization': 'OAuth AgAAAAAoc5wqAAYckc67wQ4UHEheuLDz0_25rEA'} получена ошибка: {'error': 'Wrong from_date format'}
2021-01-09 15:55:21,880, DEBUG, telegram.bot, Entering: send_message
2021-01-09 15:55:21,881, DEBUG, telegram.vendor.ptb_urllib3.urllib3.connectionpool, Starting new HTTPS connection (1): api.telegram.org
2021-01-09 15:55:22,181, DEBUG, telegram.vendor.ptb_urllib3.urllib3.connectionpool, https://api.telegram.org:443 "POST /bot1415873638:AAFaNq5fitqj7HraQWi5MOqvfOrs4P-UvFA/sendMessage HTTP/1.1" 200 776
2021-01-09 15:55:22,181, DEBUG, telegram.bot, {'message_id': 170, 'date': 1610189722, 'chat': {'id': 1081293835, 'type': 'private', 'first_name': 'Alexey', 'last_name': 'Loguntsov'}, 'text': "Бот столкнулся с ошибкой: По запросу: https://praktikum.yandex.ru/api/user_api/homework_statuses/, {'from_date': 'current_timestamp'}, {'Authorization': 'OAuth AgAAAAAoc5wqAAYckc67wQ4UHEheuLDz0_25rEA'} получена ошибка: {'error': 'Wrong from_date format'}", 'entities': [{'type': 'url', 'offset': 38, 'length': 59}], 'caption_entities': [], 'photo': [], 'new_chat_members': [], 'new_chat_photo': [], 'delete_chat_photo': False, 'group_chat_created': False, 'supergroup_chat_created': False, 'channel_chat_created': False, 'from': {'id': 1415873638, 'first_name': 'LoguntsovAE', 'is_bot': True, 'username': 'LoguntsovAE_bot'}}
2021-01-09 15:55:22,182, DEBUG, telegram.bot, Exiting: send_message
2021-01-09 15:55:22,182, INFO, root, Ботом отправленно сообщение о статусе домашки. Текст сообщения:"Бот столкнулся с ошибкой: По запросу: https://praktikum.yandex.ru/api/user_api/homework_statuses/, {'from_date': 'current_timestamp'}, {'Authorization': 'OAuth AgAAAAAoc5wqAAYckc67wQ4UHEheuLDz0_25rEA'} получена ошибка: {'error': 'Wrong from_date format'}"
2021-01-09 15:55:34,662, DEBUG, root, Бот был успешно создан
2021-01-09 15:55:34,662, INFO, root, Отправлен запрос для проверки домашки
2021-01-09 15:59:37,248, DEBUG, root, Бот был успешно создан
2021-01-09 15:59:37,249, INFO, root, Отправлен запрос для проверки домашки
2021-01-09 16:01:20,363, DEBUG, root, Бот был успешно создан
2021-01-09 16:01:20,364, INFO, root, Отправлен запрос для проверки домашки
2021-01-09 16:01:31,001, DEBUG, root, Бот был успешно создан
2021-01-09 16:01:31,001, INFO, root, Отправлен запрос для проверки домашки
2021-01-09 16:01:31,382, DEBUG, telegram.bot, Entering: send_message
2021-01-09 16:01:31,383, DEBUG, telegram.vendor.ptb_urllib3.urllib3.connectionpool, Starting new HTTPS connection (1): api.telegram.org
2021-01-09 16:01:31,724, DEBUG, telegram.vendor.ptb_urllib3.urllib3.connectionpool, https://api.telegram.org:443 "POST /bot1415873638:AAFaNq5fitqj7HraQWi5MOqvfOrs4P-UvFA/sendMessage HTTP/1.1" 200 591
2021-01-09 16:01:31,724, DEBUG, telegram.bot, {'message_id': 171, 'date': 1610190091, 'chat': {'id': 1081293835, 'type': 'private', 'first_name': 'Alexey', 'last_name': 'Loguntsov'}, 'text': 'У вас проверили работу "LoguntsovAE__api_sp1_bot.zip"!\n\nК сожалению в работе нашлись ошибки.', 'entities': [], 'caption_entities': [], 'photo': [], 'new_chat_members': [], 'new_chat_photo': [], 'delete_chat_photo': False, 'group_chat_created': False, 'supergroup_chat_created': False, 'channel_chat_created': False, 'from': {'id': 1415873638, 'first_name': 'LoguntsovAE', 'is_bot': True, 'username': 'LoguntsovAE_bot'}}
2021-01-09 16:01:31,725, DEBUG, telegram.bot, Exiting: send_message
2021-01-09 16:01:31,725, INFO, root, Ботом отправленно сообщение о статусе домашки. Текст сообщения:"У вас проверили работу "LoguntsovAE__api_sp1_bot.zip"!

К сожалению в работе нашлись ошибки."
2021-01-09 16:01:48,936, DEBUG, root, Бот был успешно создан
2021-01-09 16:01:48,937, INFO, root, Отправлен запрос для проверки домашки
2021-01-09 16:01:49,218, DEBUG, telegram.bot, Entering: send_message
2021-01-09 16:01:49,218, DEBUG, telegram.vendor.ptb_urllib3.urllib3.connectionpool, Starting new HTTPS connection (1): api.telegram.org
2021-01-09 16:01:49,530, DEBUG, telegram.vendor.ptb_urllib3.urllib3.connectionpool, https://api.telegram.org:443 "POST /bot1415873638:AAFaNq5fitqj7HraQWi5MOqvfOrs4P-UvFA/sendMessage HTTP/1.1" 200 732
2021-01-09 16:01:49,531, DEBUG, telegram.bot, {'message_id': 172, 'date': 1610190109, 'chat': {'id': 1081293835, 'type': 'private', 'first_name': 'Alexey', 'last_name': 'Loguntsov'}, 'text': 'У вас проверили работу "LoguntsovAE__api_sp1_bot.zip"!\n\nРевьюеру всё понравилось, можно приступать к следующему уроку.', 'entities': [], 'caption_entities': [], 'photo': [], 'new_chat_members': [], 'new_chat_photo': [], 'delete_chat_photo': False, 'group_chat_created': False, 'supergroup_chat_created': False, 'channel_chat_created': False, 'from': {'id': 1415873638, 'first_name': 'LoguntsovAE', 'is_bot': True, 'username': 'LoguntsovAE_bot'}}
2021-01-09 16:01:49,532, DEBUG, telegram.bot, Exiting: send_message
2021-01-09 16:01:49,532, INFO, root, Ботом отправленно сообщение о статусе домашки. Текст сообщения:"У вас проверили работу "LoguntsovAE__api_sp1_bot.zip"!

Ревьюеру всё понравилось, можно приступать к следующему уроку."
2021-01-09 16:02:15,226, DEBUG, root, Бот был успешно создан
2021-01-09 16:02:15,226, INFO, root, Отправлен запрос для проверки домашки
2021-01-09 16:02:15,588, DEBUG, telegram.bot, Entering: send_message
2021-01-09 16:02:15,588, DEBUG, telegram.vendor.ptb_urllib3.urllib3.connectionpool, Starting new HTTPS connection (1): api.telegram.org
2021-01-09 16:02:15,911, DEBUG, telegram.vendor.ptb_urllib3.urllib3.connectionpool, https://api.telegram.org:443 "POST /bot1415873638:AAFaNq5fitqj7HraQWi5MOqvfOrs4P-UvFA/sendMessage HTTP/1.1" 200 565
2021-01-09 16:02:15,912, DEBUG, telegram.bot, {'message_id': 173, 'date': 1610190135, 'chat': {'id': 1081293835, 'type': 'private', 'first_name': 'Alexey', 'last_name': 'Loguntsov'}, 'text': 'У вас проверили работу "LoguntsovAE__api_sp1_bot.zip"!\n\nЗадание находится на проверке.', 'entities': [], 'caption_entities': [], 'photo': [], 'new_chat_members': [], 'new_chat_photo': [], 'delete_chat_photo': False, 'group_chat_created': False, 'supergroup_chat_created': False, 'channel_chat_created': False, 'from': {'id': 1415873638, 'first_name': 'LoguntsovAE', 'is_bot': True, 'username': 'LoguntsovAE_bot'}}
2021-01-09 16:02:15,912, DEBUG, telegram.bot, Exiting: send_message
2021-01-09 16:02:15,912, INFO, root, Ботом отправленно сообщение о статусе домашки. Текст сообщения:"У вас проверили работу "LoguntsovAE__api_sp1_bot.zip"!

Задание находится на проверке."
